Workbook
Name customer: DATASET!$A$1:$N$251
Name NativeTimeline_Date: #N/A
Name Slicer_Category: #N/A
Name Slicer_Customer_Name: #N/A
Name Slicer_Product_Name: #N/A
Name Slicer_Quantity: #N/A
Name Slicer_Region: #N/A

Sheet Project Instructions
A1: PR. Final Project - "Data Intelligence Dashboard"
A2: Dataset: Use the 'Final Project Dataset' sheet containing 200+ records of customer transactions. Objective: Create a full-fledged analysis and reporting solution using Excel to analyze customer transactions, find insights, and build visualizations and dashboards. Key Topics to Implement: - Date & Time Functions: TODAY, NOW, DATEDIF, EOMONTH - FILTER Function for multi-value returns - Conditional Formatting with Icons/Arrows - Create Timestamp (using NOW and iterative calculations) - WHAT-IF Analysis: Scenario Manager, Goal Seek - Linear Regression using Data Analysis Toolpak - Data Analysis & Storytelling from the dataset - Use GroupBy concepts to find High-Value Customers using formulas - Create Dashboard using: - Pivot Tables - Pivot Charts (Bar, Line, Pie) - Slicers and Timelines - KPI Indicators with Conditional Formatting - Find most frequently purchased product or repeating names using formulas - Compare two lists and extract matching names in a new column - Create Abbreviations using TEXT functions - Build a final report with insights and storytelling Deliverable: - Well-structured workbook with multiple sheets (Raw Data, Analysis, Visualizations, Dashboard) - Summary Insights with key metrics: Total Revenue, Top Customers, Most Sold Products, Regional Sales - Use of all required formulas and functions as listed above

Sheet Dashboard
B6: Total Sales | E6: Total Quantity Sold | H6: Top Rigion | K6: Top Customer Nm
B7: =GETPIVOTDATA("Total_Amount",Visualizations!$A$3) -> 229192.47 | E7: =GETPIVOTDATA("Quantity",Visualizations!$G$2) -> 250 | H7: =GETPIVOTDATA("Total_Amount",Visualizations!$J$1,"Region","East") -> 59288.39 | K7: =Visualizations!A4 -> Mark Carter
A49: Dashboard Insights:
A51: The business generated Total Sales of 180,096.63 with 107 units sold during the selected period.
A52: Mark Carter is the top-performing customer, contributing the highest sales among all customers.
A53: The East region is the strongest market, contributing the largest share of total sales (28%), followed by the North region (21%).
A54: Laptop and Smartphone products are the major revenue drivers, significantly outperforming other products.
A55: Electronics dominate product demand, accounting for approximately 76% of total quantity sold, while Furniture contributes around 24%.
A56: Customer sales are highly concentrated among a few customers, indicating that a small group of customers contributes a substantial portion of overall revenue.
A57: Regional sales distribution is relatively balanced, but increasing sales efforts in South and Central regions could improve overall performance.
A59: Key Observation:
A60: The company’s revenue is primarily driven by Electronics products (especially Laptops and Smartphones) and strong sales from the East region, with Mark Carter emerging as the most valuable customer.

Sheet DATASET
A1: Transaction_ID | B1: Date | C1: Customer_ID | D1: Customer_Name | E1: Product_ID | F1: Product_Name | G1: Category | H1: Quantity | I1: Unit_Price | J1: Payment_Method | K1: Region | L1: Customer_Segment | M1: Customer_Since | N1: Total_Amount
A2: TRX0155 | B2: 45393 | C2: CUST023 | D2: Paul Baker | E2: P009 | F2: Monitor | G2: Electronics | H2: 3 | I2: 249.99 | J2: Cash | K2: Central | L2: Basic | M2: 44425 | N2: 749.97
A3: TRX0023 | B3: 45396 | C3: CUST013 | D3: Joseph Jackson | E3: P009 | F3: Monitor | G3: Electronics | H3: 3 | I3: 249.99 | J3: Credit Card | K3: Central | L3: Premium | M3: 44575 | N3: 749.97
A4: TRX0139 | B4: 45399 | C4: CUST021 | D4: Kevin Scott | E4: P005 | F4: Blender | G4: Appliances | H4: 3 | I4: 59.99 | J4: PayPal | K4: South | L4: Standard | M4: 45262 | N4: 179.97
A5: TRX0043 | B5: 45400 | C5: CUST046 | D5: Kathleen Bennett | E5: P005 | F5: Blender | G5: Appliances | H5: 3 | I5: 59.99 | J5: Cash | K5: North | L5: Premium | M5: 45114 | N5: 179.97
A6: TRX0212 | B6: 45400 | C6: CUST003 | D6: Michael Brown | E6: P008 | F6: Bookshelf | G6: Furniture | H6: 5 | I6: 149.99 | J6: Credit Card | K6: North | L6: Premium | M6: 45295 | N6: 749.95
A7: TRX0092 | B7: 45403 | C7: CUST024 | D7: Dorothy Nelson | E7: P005 | F7: Blender | G7: Appliances | H7: 2 | I7: 59.99 | J7: Cash | K7: West | L7: Standard | M7: 44746 | N7: 119.98
A8: TRX0193 | B8: 45403 | C8: CUST024 | D8: Dorothy Nelson | E8: P003 | F8: Headphones | G8: Electronics | H8: 5 | I8: 149.99 | J8: Credit Card | K8: Central | L8: Standard | M8: 44418 | N8: 749.95
A9: TRX0240 | B9: 45403 | C9: CUST017 | D9: Charles Allen | E9: P005 | F9: Blender | G9: Appliances | H9: 3 | I9: 59.99 | J9: Debit Card | K9: South | L9: Basic | M9: 45007 | N9: 179.97
A10: TRX0135 | B10: 45405 | C10: CUST009 | D10: Robert Thomas | E10: P001 | F10: Laptop | G10: Electronics | H10: 3 | I10: 899.99 | J10: PayPal | K10: East | L10: Standard | M10: 45299 | N10: 2699.97
A11: TRX0185 | B11: 45408 | C11: CUST026 | D11: Karen Hill | E11: P005 | F11: Blender | G11: Appliances | H11: 3 | I11: 59.99 | J11: Cash | K11: West | L11: Premium | M11: 45207 | N11: 179.97
A12: TRX0138 | B12: 45408 | C12: CUST022 | D12: Susan Green | E12: P008 | F12: Bookshelf | G12: Furniture | H12: 1 | I12: 149.99 | J12: Credit Card | K12: West | L12: Standard | M12: 45103 | N12: 149.99
A13: TRX0209 | B13: 45408 | C13: CUST046 | D13: Kathleen Bennett | E13: P008 | F13: Bookshelf | G13: Furniture | H13: 5 | I13: 149.99 | J13: Debit Card | K13: North | L13: Basic | M13: 44830 | N13: 749.95
... A251: TRX0064 | B251: 45758 | C251: CUST031 | D251: Steven Turner | E251: P010 | F251: Keyboard | G251: Electronics | H251: 3 | I251: 89.99 | J251: Debit Card | K251: North | L251: Premium | M251: 44878 | N251: 269.97

Sheet filter functions
A1: All the Unique Name | B1: Unique Product Name | C1: Product Category | D1: Region | G1: Filter Monitor and Electronics
A2: {=_xlfn.UNIQUE(cust[Customer_Name])} -> Paul Baker | B2: {=_xlfn.UNIQUE(DATASET!F2:F251)} -> Monitor | C2: {=_xlfn.UNIQUE(DATASET!G2:G251)} -> Electronics | D2: {=_xlfn.UNIQUE(cust[Region])} -> Central | F2: {=_xlfn._xlws.FILTER(cust[],(cust[Product_Name]="Monitor")*(cust[Category]="Electronics"),"no record")} -> TRX0155 | G2: 45393 | H2: CUST023 | I2: Paul Baker | J2: P009 | K2: Monitor | L2: Electronics | M2: 3 | N2: 249.99 | O2: Cash | P2: Central | Q2: Basic | R2: 44425 | S2: 749.97
A3: Joseph Jackson | B3: Blender | C3: Appliances | D3: South | F3: TRX0023 | G3: 45396 | H3: CUST013 | I3: Joseph Jackson | J3: P009 | K3: Monitor | L3: Electronics | M3: 3 | N3: 249.99 | O3: Credit Card | P3: Central | Q3: Premium | R3: 44575 | S3: 749.97
A4: Kevin Scott | B4: Bookshelf | C4: Furniture | D4: North | F4: TRX0222 | G4: 45410 | H4: CUST048 | I4: Virginia Sanders | J4: P009 | K4: Monitor | L4: Electronics | M4: 3 | N4: 249.99 | O4: Credit Card | P4: North | Q4: Premium | R4: 45224 | S4: 749.97
A5: Kathleen Bennett | B5: Headphones | D5: West | F5: TRX0204 | G5: 45415 | H5: CUST044 | I5: Cynthia Price | J5: P009 | K5: Monitor | L5: Electronics | M5: 4 | N5: 249.99 | O5: PayPal | P5: North | Q5: Standard | R5: 44468 | S5: 999.96
A6: Michael Brown | B6: Laptop | D6: East | F6: TRX0071 | G6: 45422 | H6: CUST036 | I6: Nancy Collins | J6: P009 | K6: Monitor | L6: Electronics | M6: 5 | N6: 249.99 | O6: Credit Card | P6: West | Q6: Standard | R6: 44525 | S6: 1249.95
A7: Dorothy Nelson | B7: Smartphone | F7: TRX0234 | G7: 45449 | H7: CUST013 | I7: Joseph Jackson | J7: P009 | K7: Monitor | L7: Electronics | M7: 5 | N7: 249.99 | O7: Credit Card | P7: East | Q7: Standard | R7: 44707 | S7: 1249.95
A8: Charles Allen | B8: Desk | F8: TRX0215 | G8: 45498 | H8: CUST047 | I8: Gerald Murphy | J8: P009 | K8: Monitor | L8: Electronics | M8: 4 | N8: 249.99 | O8: Debit Card | P8: Central | Q8: Standard | R8: 45127 | S8: 999.96
A9: Robert Thomas | B9: Coffee Maker | F9: TRX0080 | G9: 45500 | H9: CUST018 | I9: Barbara Young | J9: P009 | K9: Monitor | L9: Electronics | M9: 2 | N9: 249.99 | O9: Cash | P9: North | Q9: Premium | R9: 45164 | S9: 499.98
A10: Karen Hill | B10: Keyboard | F10: TRX0075 | G10: 45517 | H10: CUST020 | I10: Margaret Wright | J10: P009 | K10: Monitor | L10: Electronics | M10: 5 | N10: 249.99 | O10: PayPal | P10: East | Q10: Premium | R10: 44782 | S10: 1249.95
A11: Susan Green | B11: Office Chair | F11: TRX0098 | G11: 45517 | H11: CUST026 | I11: Karen Hill | J11: P009 | K11: Monitor | L11: Electronics | M11: 3 | N11: 249.99 | O11: PayPal | P11: North | Q11: Premium | R11: 44465 | S11: 749.97
A12: Peter Richardson | F12: TRX0037 | G12: 45528 | H12: CUST035 | I12: Harry Morgan | J12: P009 | K12: Monitor | L12: Electronics | M12: 2 | N12: 249.99 | O12: Cash | P12: South | Q12: Standard | R12: 44572 | S12: 499.98
A13: Dennis Gray | F13: TRX0099 | G13: 45537 | H13: CUST034 | I13: Carol Evans | J13: P009 | K13: Monitor | L13: Electronics | M13: 1 | N13: 249.99 | O13: Credit Card | P13: West | Q13: Premium | R13: 44685 | S13: 249.99
A14: Michelle Rogers | F14: TRX0074 | G14: 45537 | H14: CUST023 | I14: Paul Baker | J14: P009 | K14: Monitor | L14: Electronics | M14: 1 | N14: 249.99 | O14: Debit Card | P14: North | Q14: Premium | R14: 45332 | S14: 249.99
A15: George Adams | F15: TRX0195 | G15: 45551 | H15: CUST026 | I15: Karen Hill | J15: P009 | K15: Monitor | L15: Electronics | M15: 2 | N15: 249.99 | O15: PayPal | P15: South | Q15: Basic | R15: 44993 | S15: 499.98
A16: Mark Carter | F16: TRX0057 | G16: 45597 | H16: CUST023 | I16: Paul Baker | J16: P009 | K16: Monitor | L16: Electronics | M16: 5 | N16: 249.99 | O16: Credit Card | P16: South | Q16: Standard | R16: 44881 | S16: 1249.95
A17: Maria Garcia | F17: TRX0090 | G17: 45605 | H17: CUST020 | I17: Margaret Wright | J17: P009 | K17: Monitor | L17: Electronics | M17: 1 | N17: 249.99 | O17: Credit Card | P17: North | Q17: Premium | R17: 44828 | S17: 249.99
A18: Virginia Sanders | F18: TRX0076 | G18: 45607 | H18: CUST012 | I18: Patricia Moore | J18: P009 | K18: Monitor | L18: Electronics | M18: 4 | N18: 249.99 | O18: Credit Card | P18: West | Q18: Standard | R18: 44659 | S18: 999.96
A19: Barbara Young | F19: TRX0012 | G19: 45622 | H19: CUST045 | I19: Douglas Watson | J19: P009 | K19: Monitor | L19: Electronics | M19: 5 | N19: 249.99 | O19: Credit Card | P19: North | Q19: Basic | R19: 44873 | S19: 1249.95
A20: Patricia Moore | F20: TRX0094 | G20: 45627 | H20: CUST017 | I20: Charles Allen | J20: P009 | K20: Monitor | L20: Electronics | M20: 5 | N20: 249.99 | O20: Cash | P20: Central | Q20: Premium | R20: 44485 | S20: 1249.95
A21: Cynthia Price | F21: TRX0137 | G21: 45629 | H21: CUST011 | I21: William White | J21: P009 | K21: Monitor | L21: Electronics | M21: 4 | N21: 249.99 | O21: PayPal | P21: East | Q21: Premium | R21: 45098 | S21: 999.96
A22: Nancy Collins | F22: TRX0180 | G22: 45635 | H22: CUST036 | I22: Nancy Collins | J22: P009 | K22: Monitor | L22: Electronics | M22: 2 | N22: 249.99 | O22: Credit Card | P22: Central | Q22: Premium | R22: 44396 | S22: 499.98
A23: Linda Martin | F23: TRX0243 | G23: 45667 | H23: CUST048 | I23: Virginia Sanders | J23: P009 | K23: Monitor | L23: Electronics | M23: 5 | N23: 249.99 | O23: Credit Card | P23: South | Q23: Basic | R23: 45330 | S23: 1249.95
... A27: Emma Wilson | F27: TRX0038 | G27: 45726 | H27: CUST035 | I27: Harry Morgan | J27: P009 | K27: Monitor | L27: Electronics | M27: 1 | N27: 249.99 | O27: Cash | P27: North | Q27: Standard | R27: 45117 | S27: 249.99
A28: Steven Turner
A29: Jennifer Taylor
A30: Harry Morgan
A31: Daniel King
A32: Sharon Butler | F32: Region wise total Amount | J32: Use GroupBy concepts to find High-Value Customers using formulas | P32: Find most frequently purchased product or repeating names using formulas
A33: Sarah Davis | J33: Paul Baker | K33: =SUMIFS(cust[Total_Amount],cust[Customer_Name],J33) -> 8309.74 | M33: =LARGE(K33:K82,1) -> 15659.65 | R33: {=_xlfn._xlws.FILTER(P34:Q43, Q34:Q43 = LARGE(Q34:Q43,1), "not found")} -> Bookshelf | S33: 35
A34: Betty Campbell | F34: {=_xlfn.UNIQUE(cust[Region])} -> Central | G34: =SUMIF(cust[Region],"Central",cust[Total_Amount]) -> 41288.34 | J34: Joseph Jackson | K34: =SUMIFS(cust[Total_Amount],cust[Customer_Name],J34) -> 6949.84 | M34: =INDEX(J33:J82,MATCH(M33,K33:K82,0)) -> Mark Carter | P34: {=_xlfn.UNIQUE(cust[Product_Name])} -> Monitor | Q34: =COUNTIF(cust[Product_Name],P34) -> 26
A35: Julie Foster | F35: South | G35: =SUMIF(cust[Region],"South",cust[Total_Amount]) -> 36398.75 | J35: Kevin Scott | K35: =SUMIFS(cust[Total_Amount],cust[Customer_Name],J35) -> 3259.87 | P35: Blender | Q35: =COUNTIF(cust[Product_Name],P35) -> 29
A36: Raymond Ross | F36: North | G36: =SUMIF(cust[Region],F36,cust[Total_Amount]) -> 50808.31 | J36: Kathleen Bennett | K36: =SUMIFS(cust[Total_Amount],cust[Customer_Name],J36) -> 4309.81 | P36: Bookshelf | Q36: =COUNTIF(cust[Product_Name],P36) -> 35
A37: David Martinez | F37: West | G37: =SUMIF(cust[Region],F37,cust[Total_Amount]) -> 41408.68 | J37: Michael Brown | K37: =SUMIFS(cust[Total_Amount],cust[Customer_Name],J37) -> 6169.74 | P37: Headphones | Q37: =COUNTIF(cust[Product_Name],P37) -> 16
A38: Margaret Wright | F38: East | G38: =SUMIF(cust[Region],F38,cust[Total_Amount]) -> 59288.39 | J38: Dorothy Nelson | K38: =SUMIFS(cust[Total_Amount],cust[Customer_Name],J38) -> 8269.79 | P38: Laptop | Q38: =COUNTIF(cust[Product_Name],P38) -> 24
A39: Frank Torres | J39: Charles Allen | K39: =SUMIFS(cust[Total_Amount],cust[Customer_Name],J39) -> 5089.73 | P39: Smartphone | Q39: =COUNTIF(cust[Product_Name],P39) -> 31
A40: Gerald Murphy | J40: Robert Thomas | K40: =SUMIFS(cust[Total_Amount],cust[Customer_Name],J40) -> 3509.9 | P40: Desk | Q40: =COUNTIF(cust[Product_Name],P40) -> 26
A41: Elizabeth Hall | J41: Karen Hill | K41: =SUMIFS(cust[Total_Amount],cust[Customer_Name],J41) -> 8009.77 | P41: Coffee Maker | Q41: =COUNTIF(cust[Product_Name],P41) -> 14
A42: Lawrence Reed | J42: Susan Green | K42: =SUMIFS(cust[Total_Amount],cust[Customer_Name],J42) -> 1979.89 | P42: Keyboard | Q42: =COUNTIF(cust[Product_Name],P42) -> 34
A43: Carol Evans | J43: Peter Richardson | K43: =SUMIFS(cust[Total_Amount],cust[Customer_Name],J43) -> 5949.85 | P43: Office Chair | Q43: =COUNTIF(cust[Product_Name],P43) -> 15
...

Sheet Scenario Summary
B2: Scenario Summary
D3: Current Values: | E3: low demand | F3: High Demand | G3: medium Demand
E4: Created by Ayush Isamaliya on 24-11-2025 | F4: Created by Ayush Isamaliya on 24-11-2025 Modified by Ayush Isamaliya on 24-11-2025 | G4: Created by Ayush Isamaliya on 24-11-2025
B5: Changing Cells:
C6: $B$4 | D6: 25 | E6: 10 | F6: 25 | G6: 15
B7: Result Cells:
C8: $A$26
B9: Notes: Current Values column represents values of changing cells at
B10: time Scenario Summary Report was created. Changing cells for each
B11: scenario are highlighted in gray.

Sheet if anaylsis
A3: Scenario Manager (Best for Unit_Price & Quantity changes) | G3: Data Table (Best for Forecasting using Quantity & Unit Price)
A4: Quantity | B4: 25 | F4: Qty | G4: Unit Price
A5: Unit Price | B5: 25 | G5: =B12 -> 100 | H5: 10 | I5: 50 | J5: 100 | K5: 200 | L5: 500
A6: Total Amount | B6: =B4*B5 -> 625 | G6: 5 | H6: 50 | I6: 250 | J6: 500 | K6: 1000 | L6: 2500
G7: 10 | H7: 100 | I7: 500 | J7: 1000 | K7: 2000 | L7: 5000
G8: 20 | H8: 200 | I8: 1000 | J8: 2000 | K8: 4000 | L8: 10000
A9: Goal Seek (Best for Quantity, Unit_Price, Total_Amount) | G9: 50 | H9: 500 | I9: 2500 | J9: 5000 | K9: 10000 | L9: 25000
A10: Quantity | B10: 5 | G10: 100 | H10: 1000 | I10: 5000 | J10: 10000 | K10: 20000 | L10: 50000
A11: Unit Price | B11: 20
A12: Total Amount | B12: =$B$10*$B$11 -> 100

Sheet Cleaned
A1: Transaction_ID | B1: Date | C1: Customer_ID | D1: Customer_Name | E1: Product_ID | F1: Product_Name | G1: Category | H1: Quantity | I1: Unit_Price | J1: Payment_Method | K1: Region | L1: Customer_Segment | M1: Customer_Since | N1: Total_Amount
A2: TRX0155 | B2: 45393 | C2: CUST023 | D2: Paul Baker | E2: P009 | F2: Monitor | G2: Electronics | H2: 3 | I2: 249.99 | J2: Cash | K2: Central | L2: Basic | M2: 44425 | N2: 749.97
A3: TRX0023 | B3: 45396 | C3: CUST013 | D3: Joseph Jackson | E3: P009 | F3: Monitor | G3: Electronics | H3: 3 | I3: 249.99 | J3: Credit Card | K3: Central | L3: Premium | M3: 44575 | N3: 749.97 | P3: Year | Q3: Month | R3: End of Month | S3: Day Diiff
A4: TRX0139 | B4: 45399 | C4: CUST021 | D4: Kevin Scott | E4: P005 | F4: Blender | G4: Appliances | H4: 3 | I4: 59.99 | J4: PayPal | K4: South | L4: Standard | M4: 45262 | N4: 179.97 | P4: {=YEAR(tblSales[Date])} -> 2024 | Q4: {=TEXT(tblSales[Date],"mmmm")} -> April | R4: =EOMONTH(B2,MONTH(B2)) -> 45535 | S4: =DATEDIF(M2,B2,"d") -> 968
A5: TRX0043 | B5: 45400 | C5: CUST046 | D5: Kathleen Bennett | E5: P005 | F5: Blender | G5: Appliances | H5: 3 | I5: 59.99 | J5: Cash | K5: North | L5: Premium | M5: 45114 | N5: 179.97 | P5: 2024 | Q5: April | R5: =EOMONTH(B3,MONTH(B3)) -> 45535 | S5: =DATEDIF(M3,B3,"d") -> 821
A6: TRX0212 | B6: 45400 | C6: CUST003 | D6: Michael Brown | E6: P008 | F6: Bookshelf | G6: Furniture | H6: 5 | I6: 149.99 | J6: Credit Card | K6: North | L6: Premium | M6: 45295 | N6: 749.95 | P6: 2024 | Q6: April | R6: =EOMONTH(B4,MONTH(B4)) -> 45535 | S6: =DATEDIF(M4,B4,"d") -> 137
A7: TRX0092 | B7: 45403 | C7: CUST024 | D7: Dorothy Nelson | E7: P005 | F7: Blender | G7: Appliances | H7: 2 | I7: 59.99 | J7: Cash | K7: West | L7: Standard | M7: 44746 | N7: 119.98 | P7: 2024 | Q7: April | R7: =EOMONTH(B5,MONTH(B5)) -> 45535 | S7: =DATEDIF(M5,B5,"d") -> 286
A8: TRX0193 | B8: 45403 | C8: CUST024 | D8: Dorothy Nelson | E8: P003 | F8: Headphones | G8: Electronics | H8: 5 | I8: 149.99 | J8: Credit Card | K8: Central | L8: Standard | M8: 44418 | N8: 749.95 | P8: 2024 | Q8: April | R8: =EOMONTH(B6,MONTH(B6)) -> 45535 | S8: =DATEDIF(M6,B6,"d") -> 105
A9: TRX0240 | B9: 45403 | C9: CUST017 | D9: Charles Allen | E9: P005 | F9: Blender | G9: Appliances | H9: 3 | I9: 59.99 | J9: Debit Card | K9: South | L9: Basic | M9: 45007 | N9: 179.97 | P9: 2024 | Q9: April | R9: =EOMONTH(B7,MONTH(B7)) -> 45535 | S9: =DATEDIF(M7,B7,"d") -> 657
A10: TRX0135 | B10: 45405 | C10: CUST009 | D10: Robert Thomas | E10: P001 | F10: Laptop | G10: Electronics | H10: 3 | I10: 899.99 | J10: PayPal | K10: East | L10: Standard | M10: 45299 | N10: 2699.97 | P10: 2024 | Q10: April | R10: =EOMONTH(B8,MONTH(B8)) -> 45535 | S10: =DATEDIF(M8,B8,"d") -> 985
A11: TRX0185 | B11: 45408 | C11: CUST026 | D11: Karen Hill | E11: P005 | F11: Blender | G11: Appliances | H11: 3 | I11: 59.99 | J11: Cash | K11: West | L11: Premium | M11: 45207 | N11: 179.97 | P11: 2024 | Q11: April | R11: =EOMONTH(B9,MONTH(B9)) -> 45535 | S11: =DATEDIF(M9,B9,"d") -> 396
A12: TRX0138 | B12: 45408 | C12: CUST022 | D12: Susan Green | E12: P008 | F12: Bookshelf | G12: Furniture | H12: 1 | I12: 149.99 | J12: Credit Card | K12: West | L12: Standard | M12: 45103 | N12: 149.99 | P12: 2024 | Q12: April | R12: =EOMONTH(B10,MONTH(B10)) -> 45535 | S12: =DATEDIF(M10,B10,"d") -> 106
A13: TRX0209 | B13: 45408 | C13: CUST046 | D13: Kathleen Bennett | E13: P008 | F13: Bookshelf | G13: Furniture | H13: 5 | I13: 149.99 | J13: Debit Card | K13: North | L13: Basic | M13: 44830 | N13: 749.95 | P13: 2024 | Q13: April | R13: =EOMONTH(B11,MONTH(B11)) -> 45535 | S13: =DATEDIF(M11,B11,"d") -> 201
A14: TRX0246 | B14: 45408 | C14: CUST041 | D14: Peter Richardson | E14: P008 | F14: Bookshelf | G14: Furniture | H14: 3 | I14: 149.99 | J14: Cash | K14: North | L14: Premium | M14: 44806 | N14: 449.97 | P14: 2024 | Q14: April | R14: =EOMONTH(B12,MONTH(B12)) -> 45535 | S14: =DATEDIF(M12,B12,"d") -> 305
A15: TRX0067 | B15: 45409 | C15: CUST043 | D15: Dennis Gray | E15: P005 | F15: Blender | G15: Appliances | H15: 3 | I15: 59.99 | J15: Credit Card | K15: North | L15: Standard | M15: 45351 | N15: 179.97 | P15: 2024 | Q15: April | R15: =EOMONTH(B13,MONTH(B13)) -> 45535 | S15: =DATEDIF(M13,B13,"d") -> 578
A16: TRX0191 | B16: 45409 | C16: CUST038 | D16: Michelle Rogers | E16: P002 | F16: Smartphone | G16: Electronics | H16: 3 | I16: 699.99 | J16: Credit Card | K16: West | L16: Basic | M16: 44577 | N16: 2099.97 | P16: 2024 | Q16: April | R16: =EOMONTH(B14,MONTH(B14)) -> 45535 | S16: =DATEDIF(M14,B14,"d") -> 602
... A251: TRX0064 | B251: 45758 | C251: CUST031 | D251: Steven Turner | E251: P010 | F251: Keyboard | G251: Electronics | H251: 3 | I251: 89.99 | J251: Debit Card | K251: North | L251: Premium | M251: 44878 | N251: 269.97 | P251: 2025 | Q251: April | R251: =EOMONTH(B249,MONTH(B249)) -> 45900 | S251: =DATEDIF(M249,B249,"d") -> 849
P252: 2025 | Q252: April | R252: =EOMONTH(B250,MONTH(B250)) -> 45900 | S252: =DATEDIF(M250,B250,"d") -> 670
P253: 2025 | Q253: April | R253: =EOMONTH(B251,MONTH(B251)) -> 45900 | S253: =DATEDIF(M251,B251,"d") -> 880

Sheet Visualizations
D1: Product Wise total Sales | G1: Categgory wise total Quantity | J1: Row Labels | K1: Sum of Total_Amount
A2: Customer wise total Sales | D2: Row Labels | E2: Sum of Total_Amount | G2: Row Labels | H2: Count of Quantity | J2: East | K2: 59288.39
A3: Row Labels | B3: Sum of Total_Amount | D3: Laptop | E3: 67499.25 | G3: Appliances | H3: 43 | J3: North | K3: 50808.31
A4: Mark Carter | B4: 15659.65 | D4: Smartphone | E4: 67199.04 | G4: Electronics | H4: 131 | J4: West | K4: 41408.68
A5: Edward Mitchell | B5: 11919.77 | D5: Desk | E5: 23399.22 | G5: Furniture | H5: 76 | J5: Central | K5: 41288.34
A6: Barbara Young | B6: 10649.8 | D6: Monitor | E6: 21999.12 | G6: Grand Total | H6: 250 | J6: South | K6: 36398.75
A7: Patricia Moore | B7: 9799.73 | D7: Bookshelf | E7: 15298.98 | J7: Grand Total | K7: 229192.47
A8: Paul Baker | B8: 8309.74 | D8: Office Chair | E8: 10399.48
A9: Dorothy Nelson | B9: 8269.79 | D9: Keyboard | E9: 8009.11
A10: Karen Hill | B10: 8009.77 | D10: Headphones | E10: 7049.53
A11: Daniel King | B11: 7309.8 | D11: Blender | E11: 5219.13 | G11: Row Labels | H11: Sum of Total_Amount
A12: Lawrence Reed | B12: 6989.77 | D12: Coffee Maker | E12: 3119.61 | G12: 2021 | H12: 44668.33
A13: Joseph Jackson | B13: 6949.84 | D13: Grand Total | E13: 229192.47 | G13: 2022 | H13: 81817.28
A14: Helen Roberts | B14: 6459.79 | G14: 2023 | H14: 77267.52
A15: Gerald Murphy | B15: 6379.87 | G15: 2024 | H15: 25439.34
A16: Sandra Phillips | B16: 6349.83 | G16: Grand Total | H16: 229192.47
A17: Michael Brown | B17: 6169.74
A18: Peter Richardson | B18: 5949.85
A19: Betty Campbell | B19: 5649.84
A20: Sharon Butler | B20: 5619.87
A21: Harry Morgan | B21: 5519.89
A22: Sarah Davis | B22: 5499.81
A23: Charles Allen | B23: 5089.73
A24: Douglas Watson | B24: 4829.89
A25: Virginia Sanders | B25: 4789.79
A26: William White | B26: 4749.91
A27: Jennifer Taylor | B27: 4739.85
A28: Kathleen Bennett | B28: 4309.81
... A54: Grand Total | B54: 229192.47
